Workbook

Sheet Surat
A2: Urutan Surat di Quran | B2: Arabic | C2: Idn | D2: Arti | E2: Jumlah Ayat | F2: Muhammad's potential personal motivations and psychological state | G2: Analisis Kritis | H2: Rev | I2: Konteks Lama | J2: kritik terisi | L2: asbabun nuzul terisi | N2: logical fallacy terisi | P2: MORAL CONCERNS | R2: SCIENTIFIC ERRORS | T2: CONTRADICTIONS
A3: 1 | B3: الفاتحة | C3: Al-Fatihah | D3: Pembukaan | E3: 7 | F3: Historical Context: Early Meccan period establishing core prayer text. Psychological State: Need to consolidate early followers Personal Goal: Establish unique religious identity Potential Motivation: - Creates dependency through required daily prayers - Positions himself as intermediary to divine guidance - Establishes ritual that centers around his teachings | G3: Al-Fatihah, meskipun singkat (tujuh ayat), berfungsi sebagai pembukaan spiritual Quran dan mengandung beberapa isu kritis yang bernilai untuk dianalisis. ## Struktur Logika yang Problematik Surah ini dimulai dengan invokasi kepada Allah ("dengan menyebut nama Allah yang Maha Pemurah lagi Maha Penyayang"). Struktur ini menetapkan fondasi teologis untuk seluruh Quran melalui asumsi monoteisme absolut tanpa justifikasi rasional. Penggunaan "Tuhan semesta alam" (rabb al-'alamin) merupakan klaim universalis yang mengecualikan perspektif non-monoteistik dan keberagaman spiritual yang nyata dalam masyarakat majemuk, tanpa menyediakan argument untuk mendukung klaim ini. ## Kontradiksi Internal Sifat Ilahi Ayat 3 menggambarkan Allah sebagai "Maha Pemurah lagi Maha Penyayang" (ar-Rahman ar-Rahim). Namun, sifat-sifat ini bertentangan secara fundamental dengan penggambaran Allah di tempat lain dalam Quran. Ayat 4:56 mendeskripsikan Allah mengganti kulit manusia yang terbakar agar mereka terus merasakan siksaan neraka — suatu tindakan yang tidak dapat didamaikan dengan belas kasih sejati. Kontradiksi ini antara sifat rahmat dan perilaku kejam menunjukkan inkonsistensi teologis yang dalam dalam penggambaran ilahi. ## Argumentum ad Baculum dan Sistem Peradilan Retributif Ayat 4 menyebutkan "hari pembalasan" (yawm ad-din) sebagai aspek fundamental kekuasaan Allah. Penekanan pada konsekuensi menghukum digunakan sebagai dasar untuk memperkuat kepercayaan, bukan melalui argumentasi rasional atau bukti empiris. Ini adalah contoh Argumentum ad Baculum — penggunaan ancaman (hukuman akhirat) untuk memvalidasi klaim keagamaan. Lebih lanjut, konsep "hari pembalasan" mengandaikan sistem keadilan retributif murni — hukuman yang setara dengan dosa — yang melampaui standar etika modern yang menekankan rehabilitasi, restorasi, dan proporsionalitas. Konteks abad ke-7 ketika Quran ditulis mewarisi tradisi hukum retributif dari budaya Semitis kuno, namun ini tidak membuatnya etis valid dalam konteks kontemporer. ## Subordinasi Agen Manusia Ayat 5 menyatakan "hanya kepada Engkaulah kami sembah, dan hanya kepada Engkaulah kami meminta pertolongan". Formulasi ini merefleksikan ketergantungan total pada entitas eksternal (ilahi) untuk keberhasilan dan pertolongan. Sementara permintaan dukungan adalah bagian alami dari pengalaman manusia, frasa "hanya kepada Engkau" membatasi konsepsi kemandirian manusia, kerja sama sosial, dan kapasitas intrinsik untuk memecahkan masalah melalui usaha kolektif. Struktur kepercayaan yang didorong oleh ayat ini berpotensi mengurangi tanggung jawab moral manusia atas tindakan mereka sendiri, dengan mengalihkan agensi ke otoritas ilahi. ## Dikotomi Moral yang Menyederhanakan Ayat 7 membagi manusia menjadi tiga kategori yang didefinisikan secara mutlak dan saling eksklusif: 1. "Orang-orang yang telah Engkau beri nikmat" — kelompok pilihan/berkah 2. "Mereka yang dimurkai" — kelompok yang menerima kemarahan ilahi 3. "Mereka yang sesat" — kelompok yang tersesat Dikotomi ini adalah contoh dari False Dichotomy atau False Dilemma. Realitas manusia jauh lebih kompleks: masyarakat terdiri dari individu dengan spektrum kepercayaan yang beragam, tingkat ketaatan yang bervariasi, komitmen moral yang berlapis, dan pengalaman spiritual yang heterogen. Pembagian sederhana menjadi tiga kategori ini mengabaikan nuansa dan kompleksitas ini. Lebih bermasalah lagi, dikotomi ini mendorong polarisasi moral dan sikap superioritas kelompok. Mereka yang mengidentifikasi diri dengan "diberi nikmat" — yaitu, Muslim yang taat — dapat mengembangkan pandangan hierarchis tentang kelompok manusia lain sebagai "dimurkai" atau "sesat". Struktur naratif ini mendukung: - Sikap superioritas terhadap kelompok non-Muslim - Stigmatisasi terhadap mereka yang dipandang "sesat" (misalnya, Muslim yang tidak taat, ateis, penganut agama lain) - Pemisahan sosial dan eksklusivisme komunal yang membatasi empati lintas kepercayaan Dalam konteks masyarakat plural, struktur dikotomi ini menjadi fondasi teologis untuk diskriminasi dan dehumanisasi "yang lain". ## Kesimpulan Meskipun Al-Fatihah sering dipandang sebagai doa sederhana dan mulia, analisis kritis mengungkapkan beberapa lapisan isu: fondasi argumentatif yang lemah, kontradiksi teologis, penggunaan ancaman sebagai alat persuasi, pengurangan agensi manusia, dan struktur moral yang mempromosikan polarisasi dan superioritas kelompok. Surah ini menetapkan tonalitas untuk interpretasi Quran secara keseluruhan, dan isu-isu ini meresonansi melalui teks yang lebih panjang. | H3: 5 | I3: Konteks Sejarah: Periode awal Mekah yang menetapkan teks doa inti. Keadaan Psikologis: Perlu mengkonsolidasikan pengikut awal Tujuan Pribadi: Membangun identitas keagamaan yang unik Motivasi Potensial: - Menciptakan ketergantungan melalui doa harian yang wajib - Memposisikan diri sebagai perantara bimbingan ilahi - Membangun ritual yang berpusat pada ajarannya | J3: =COUNTIFS(bedah!$C:$C,Surat!$B3,bedah!I:I,"<>") -> 1 | K3: =J3/$E3 -> 0.14285714 | L3: =COUNTIFS(bedah!$C:$C,Surat!$B3,bedah!J:J,"<>") -> 7 | M3: =L3/$E3 -> 1 | N3: =COUNTIFS(bedah!$C:$C,Surat!$B3,bedah!K:K,"<>") -> 2 | O3: =N3/$E3 -> 0.28571429 | P3: =COUNTIFS(bedah!$C:$C,Surat!$B3,bedah!L:L,"<>") -> 1 | Q3: =P3/$E3 -> 0.14285714 | R3: =COUNTIFS(bedah!$C:$C,Surat!$B3,bedah!M:M,"<>") -> 0 | S3: =R3/$E3 -> 0 | T3: =COUNTIFS(bedah!$C:$C,Surat!$B3,bedah!N:N,"<>") -> 1 | U3: =T3/$E3 -> 0.14285714
A4: 2 | B4: البقرة | C4: Al-Baqarah | D4: Sapi | E4: 286 | F4: Historical Context: Medina - Early community-building period, establishing laws while dealing with Jewish tribes Psychological State: Comprehensive law-giving and community organization Potential Motivations: - Using extended Jewish stories to establish new authority - Building complete social-religious framework - Creating clear boundaries with other faiths - Converting existing practices into new system - Establishing distinct religious identity | G4: Al-Baqarah: Surat terpanjang dalam Al-Quran, sekaligus yang paling penuh masalah. Ini bukan serangan — ini pembacaan teks secara apa adanya. Determinisme vs. Kehendak Bebas — Kontradiksi Fundamental: Ayat 6–7 menyatakan Allah mengunci hati orang kafir sehingga mereka tidak akan pernah beriman. Ayat 286 menyatakan Allah tidak membebani jiwa melebihi kemampuannya. Dua klaim ini tidak bisa berdiri bersamaan: kalau hati sudah dikunci Allah, atas dasar apa manusia dihukum? Ini bukan nuansa teologis — ini kontradiksi logis. Circular Reasoning sebagai Pondasi: Ayat 2 mengklaim kitab ini tidak diragukan. Ayat 23 meminta yang meragukan untuk mendatangkan satu surat "semisal" — dengan standar yang ditentukan sendiri oleh sumber yang sedang diperdebatkan. Ini bukan argumen, ini tautologi yang dibungkus tantangan. Narasi Adam yang Berantakan: Ayat 36–38 memerintahkan Adam turun dua kali dari surga. Ini bukan sastra — ini indikasi penggabungan dua versi cerita yang berbeda (dari Surat 7 dan Surat 20) secara tidak rapi. Lebih jauh: Surat 2 mencatat pengampunan Adam SETELAH perintah turun (37), sementara Surat 20 mencatat pengampunan SEBELUM perintah turun (20:122). Dua teks yang sama-sama diklaim wahyu tidak boleh saling membantah urutan kronologis. Kosmologi Abad ke-7 yang Ditetapkan sebagai Doktrin: Ayat 22 menggambarkan langit sebagai "bangunan" di atas bumi — kanopi kosmos pra-ilmiah. Ayat 29 menyatakan bumi diciptakan lebih dulu, baru langit dijadikan tujuh lapis — bertentangan dengan kosmologi modern (bumi terbentuk dari materi bintang yang sudah ada sebelumnya). Ayat 258 mengutip argumen Ibrahim "Allah mendatangkan matahari dari timur" — bahasa Arab menunjukkan matahari yang bergerak aktif. Ini bukan metafora; ini perspektif geosentris yang tidak pernah dikoreksi dalam teks. Bunuhlah Dirimu sebagai Pertobatan: Ayat 54 memerintahkan Bani Israel bertobat dengan cara "membunuh diri sendiri." Tidak ada justifikasi etis yang bisa membuat kematian menjadi syarat pengampunan dari entitas yang disebut Maha Penyayang. Ini bukan ujian — ini absurd secara moral. Perempuan: Objek, Saksi Kelas Dua, Tanpa Otonomi: Ayat 223 menyebut istri sebagai "ladang" yang dikerjakan sesuka hati. Ayat 228 menetapkan lelaki satu derajat di atas perempuan. Ayat 282 menetapkan kesaksian dua perempuan setara satu laki-laki. Ayat 230 melarang rujuk kecuali si istri menikah dulu dengan laki-laki lain (tahlil) — sebuah konstruksi hukum yang merendahkan martabat perempuan menjadi instrumen prosedur. Ini bukan soal konteks budaya abad ke-7. Ini prinsip yang dinyatakan eksplisit sebagai hukum. Tidak Ada Paksaan — Kecuali Kalau Mau Diperangi: Ayat 256 menyatakan "tidak ada paksaan dalam agama." Ayat 193 menyatakan "perangilah mereka sampai tidak ada fitnah dan agama hanya untuk Allah." Dua klaim ini tidak bisa ada dalam satu kitab yang konsisten. Salah satunya bohong, atau keduanya harus ditafsirkan sampai kehilangan makna aslinya. Riba: Taat atau Berperang dengan Tuhan: Ayat 278 memberi ultimatum: tinggalkan sisa riba atau "berperang dengan Allah dan RasulNya." Tidak ada ruang negosiasi, tidak ada gradasi, tidak ada dialog. Ini bukan hukum — ini ancaman eksistensial yang dikemas sebagai regulasi. Kisah Sapi Betina yang Tidak Koheren: Ayat 67 memerintahkan sembelih sapi. Ayat 68–71 menambah spesifikasi berlapis — warna, usia, kondisi — tanpa alasan yang dijelaskan. Ayat 72–73 tiba-tiba berubah menjadi ritual pembuktian kasus pembunuhan. Tidak ada benang naratif yang menghubungkan perintah awal dengan resolusi akhir secara logis. Fitnah Lebih Besar dari Pembunuhan: Ayat 217 menetapkan hierarki nilai yang menempatkan gangguan terhadap agama di atas hilangnya nyawa manusia. Ketika sebuah teks suci menyatakan hal itu secara eksplisit, ia telah menyediakan justifikasi teologis untuk kekerasan atas nama pertahanan agama. Sistem Koreksi Internal (Nasakh): Ayat 106 memperkenalkan konsep penggantian ayat — Allah menukar perintah dengan yang lebih baik atau sebanding. Kalau wahyu ini sempurna dari awal, untuk apa mekanisme koreksi internal? Kalau tidak sempurna, klaim kesempurnaan harus dicabut. Bani Israel sebagai Kambing Hitam Struktural: Sepanjang surat ini, Bani Israel diposisikan sebagai kelompok yang selalu membangkang, membunuh nabi, dan mengkhianati perjanjian (61, 87, 100). Ini bukan catatan sejarah — ini pola narasi yang sistematis untuk mendelegitimasi satu komunitas dan membenarkan penggantiannya oleh komunitas baru. Qishas: Keadilan Primitif Dikodifikasi: Ayat 178–179 menetapkan "mata ganti mata" sebagai sistem keadilan. Sistem hukum modern bergerak ke arah rehabilitasi dan pemulihan — bukan pembalasan setimpal yang mengunci siklus dendam. Kontradiksi Syafaat: Ayat 47 dan 123 menegaskan tidak ada syafaat yang berguna di Hari Kiamat. Ini bertentangan dengan 20:109 yang mengizinkan syafaat bagi mereka yang mendapat izin Allah — dan dengan seluruh tradisi hadis tentang syafaat Nabi. Keduanya tidak bisa sama-sama benar. Kesimpulan: Al-Baqarah lebih menyerupai konstitusi komunitas baru yang sedang membangun otoritas — penuh aturan, ancaman, dan narasi yang mengonstruksi musuh. Bukan wahyu universal yang sempurna dari entitas yang Maha Mengetahui dan Maha Adil. Kalau benar berasal dari Tuhan Yang Maha Sempurna, teks ini tidak seharusnya mengandung kontradiksi internal, kesalahan kosmologi, dan masalah etis yang tidak bisa diselesaikan dengan tafsir apapun. | H4: 87 | I4: Konteks Sejarah: Madinah - Periode awal pembangunan komunitas, menetapkan hukum sambil berurusan dengan suku-suku Yahudi Keadaan Psikologis: Pemberian hukum yang komprehensif dan organisasi komunitas Motivasi Potensial: - Menggunakan kisah-kisah Yahudi yang diperluas untuk membangun otoritas baru - Membangun kerangka kerja sosial-keagamaan yang lengkap - Menciptakan batasan yang jelas dengan agama lain - Mengubah praktik yang ada menjadi sistem baru - Membangun identitas keagamaan yang berbeda | J4: =COUNTIFS(bedah!$C:$C,Surat!$B4,bedah!I:I,"<>") -> 7 | K4: =J4/$E4 -> 0.024475524 | L4: =COUNTIFS(bedah!$C:$C,Surat!$B4,bedah!J:J,"<>") -> 286 | M4: =L4/$E4 -> 1 | N4: =COUNTIFS(bedah!$C:$C,Surat!$B4,bedah!K:K,"<>") -> 78 | O4: =N4/$E4 -> 0.27272727 | P4: =COUNTIFS(bedah!$C:$C,Surat!$B4,bedah!L:L,"<>") -> 60 | Q4: =P4/$E4 -> 0.20979021 | R4: =COUNTIFS(bedah!$C:$C,Surat!$B4,bedah!M:M,"<>") -> 14 | S4: =R4/$E4 -> 0.048951049 | T4: =COUNTIFS(bedah!$C:$C,Surat!$B4,bedah!N:N,"<>") -> 17 | U4: =T4/$E4 -> 0.059440559
A5: 3 | B5: اٰل عمران | C5: Ali 'Imran | D5: Keluarga Imran | E5: 200 | F5: Historical Context: Medina - After Uhud defeat, dealing with Christian delegation from Najran Psychological State: Building resilience after setback while engaging Christians Potential Motivations: - Using Mary/Jesus stories to engage Christians while marking differences - Building defeat into larger victory narrative - Creating martyrdom value system after losses - Converting military loss into spiritual testing - Establishing usury prohibition and economic framework | G5: Ali Imran: Konsolidasi Ideologi dan Legitimasi Kekuasaan Pasca-Badar Diturunkan di Madinah antara tahun 2-3 H, Ali Imran mencerminkan momen kritis komunitas Muslim awal — setelah kemenangan Badar dan menjelang kekalahan Uhud. Surat ini bukan sekadar instruksi teologis; ia adalah dokumen konsolidasi identitas kelompok yang mendefinisikan batas tegas antara in-group (mukmin) dan out-group (kafir, Ahli Kitab, munafik). Eksklusivisme sebagai fondasi. Ayat 19 dan 85 menegaskan bahwa hanya Islam yang diterima Allah, sementara semua agama lain adalah bathil. Ini bukan posisi inklusif yang mengakui nilai universal kebenaran — melainkan klaim monopoli keselamatan yang, secara logis, menjadikan miliaran manusia dari tradisi lain sebagai objek penolakan ilahi. Klaim ini tidak didukung argumen epistemologis — ia ditegakkan melalui otoritas wahyu (circular reasoning) dan ancaman hukuman (ad baculum). Segregasi sosial yang terlembaga. Ayat 28 dan 118 melarang secara eksplisit menjadikan non-Muslim sebagai teman dekat atau kepercayaan, dengan justifikasi bahwa mereka 'tidak menginginkan kebaikan bagi kalian'. Generalisasi ini — mengafirmasi prasangka terhadap seluruh kelompok berdasarkan keyakinan — mengondisikan ketidakpercayaan sistemik dan isolasi sosial. Dalam konteks komunitas plural modern, perintah seperti ini berpotensi menjadi fondasi diskriminasi terstruktur. Glorifikasi perang dan kematian. Ayat 157, 169, dan 195 membangun retorika mulia seputar kematian di medan perang. Syahid 'hidup di sisi Tuhan', kematian dalam perang lebih baik dari kehidupan biasa. Framing ini memuliakan pengorbanan diri dan dapat menyuburkan ideologi yang merendahkan nilai kehidupan — sebuah isu yang sangat relevan dalam konteks radikalisme modern. Kontradiksi tekstual. Surat ini mengandung setidaknya tiga kontradiksi terverifikasi: (1) 3:7 mengakui adanya ayat yang hanya Allah tahu maknanya, bertentangan dengan klaim 12:111 bahwa Quran menjelaskan segala sesuatu; (2) jumlah malaikat di Badar berbeda antara 3:124 (3.000) dan 8:9 (1.000); (3) cara penyampaian kabar kepada Maryam berbeda antara 3:45 (malaikat jamak) dan 19:17 (satu roh berbentuk manusia). Strategi retorika ancaman. Sejumlah ayat (4, 10, 56, 151) menggunakan ancaman azab sebagai instrumen utama kepatuhan. Ini adalah pola argumentum ad baculum — bukan ajakan beriman berdasarkan bukti atau kebaikan, melainkan kepatuhan berbasis ketakutan terhadap konsekuensi negatif. Allah bahkan secara aktif 'memasukkan rasa takut ke hati orang kafir' (151) — melegitimasi teror sebagai alat ilahi. Ali Imran adalah teks yang memperlihatkan bagaimana komunitas keagamaan mengkonsolidasikan identitasnya melalui pembedaan tajam antara kami dan mereka, menggunakan kombinasi ancaman, glorifikasi, dan klaim keistimewaan. Nilai historisnya sebagai rekaman mentalitas komunitas Madinah abad ke-7 tidak diragukan — namun aplikasinya secara harfiah dalam konteks modern mengundang perhatian kritis yang serius. | H5: 89 | I5: Konteks Sejarah: Madinah - Setelah kekalahan Uhud, berurusan dengan delegasi Kristen dari Najran Kondisi Psikologis: Membangun ketahanan setelah kemunduran sambil melibatkan umat Kristen Motivasi Potensial: - Menggunakan kisah Maria/Yesus untuk melibatkan umat Kristen sambil menyoroti perbedaan - Membangun kekalahan menjadi narasi kemenangan yang lebih besar - Menciptakan sistem nilai kemartiran setelah kekalahan - Mengubah kekalahan militer menjadi ujian spiritual - Menetapkan larangan riba dan kerangka ekonomi | J5: =COUNTIFS(bedah!$C:$C,Surat!$B5,bedah!I:I,"<>") -> 8 | K5: =J5/$E5 -> 0.04 | L5: =COUNTIFS(bedah!$C:$C,Surat!$B5,bedah!J:J,"<>") -> 200 | M5: =L5/$E5 -> 1 | N5: =COUNTIFS(bedah!$C:$C,Surat!$B5,bedah!K:K,"<>") -> 17 | O5: =N5/$E5 -> 0.085 | P5: =COUNTIFS(bedah!$C:$C,Surat!$B5,bedah!L:L,"<>") -> 30 | Q5: =P5/$E5 -> 0.15 | R5: =COUNTIFS(bedah!$C:$C,Surat!$B5,bedah!M:M,"<>") -> 5 | S5: =R5/$E5 -> 0.025 | T5: =COUNTIFS(bedah!$C:$C,Surat!$B5,bedah!N:N,"<>") -> 5 | U5: =T5/$E5 -> 0.025
A6: 4 | B6: النساۤء | C6: An-Nisa' | D6: Wanita | E6: 176 | F6: Historical Context: Medina - Post-Uhud, many widows/orphans, new social order needed Psychological State: Establishing comprehensive social reform Potential Motivations: - Using orphan protection to build moral authority - Building detailed women's rights framework - Creating new inheritance system - Converting tribal family customs into Islamic law - Establishing marriage and divorce regulations | G6: An-Nisa: Kitab Hukum Patriarkal, Genosida Religius, dan Kekerasan Melembaga Surat An-Nisa, dengan 176 ayat yang turun di Madinah pascaperang Uhud, adalah surat paling komprehensif sekaligus paling bermasalah dalam Al-Qur'an. Sementara judulnya "Perempuan" menjanjikan perhatian pada nasib perempuan, isi surat ini justru menjadi instrumen yang melembagakan diskriminasi gender, kekerasan domestik, perbudakan seksual, dan doktrin perang agama. Surat ini perlu dibaca secara utuh — bukan sebagai kumpulan ayat yang dapat diisolasi — untuk memahami ekosistem hukum yang dibangunnya. **I. Diskriminasi Gender yang Dikodifikasi sebagai Hukum Ilahi** Sejak ayat pertama, surat ini membangun fondasi androsentris: manusia diciptakan dari "diri yang satu" dan perempuan diciptakan darinya (4:1). Struktur penciptaan ini bukan detail kosmologis yang netral — ia menetapkan laki-laki sebagai standar kemanusiaan dan perempuan sebagai turunan. Ini adalah premis yang kemudian mengalir ke seluruh sistem hukum surat. Sistem waris di ayat 11-12 mengkodifikasi ketidaksetaraan secara matematis: "bagian seorang anak laki-laki sama dengan bagian dua anak perempuan." Tidak ada argumen rasional yang diberikan mengapa jenis kelamin menentukan kapasitas mewarisi. Yang lebih buruk, formula ini ternyata mengandung cacat matematika fatal: beberapa skenario menghasilkan total bagian melebihi 100% — misalnya ketika terdapat istri (1/8), anak perempuan (2/3), ayah (1/6), dan ibu (1/6), totalnya menjadi 27/24. Masalah ini tidak diselesaikan oleh teks sendiri, melainkan harus diperbaiki lewat inovasi post-Qur'anik yang disebut 'awl oleh Khalifah Umar. Sistem yang diklaim sempurna ternyata memerlukan perbaikan oleh manusia. Kontradiksi internal yang paling telanjang dalam surat ini adalah antara ayat 3 dan ayat 129. Ayat 3 mengizinkan poligami dengan syarat "berlaku adil." Ayat 129 mengakui: "Kamu sekali-kali tidak akan dapat berlaku adil di antara istri-istrimu, walaupun kamu sangat ingin berbuat demikian." Satu surat, dua ayat, satu izin dan satu pengakuan bahwa syarat izin tersebut mustahil dipenuhi. **II. Legalisasi Kekerasan Domestik** Ayat 34 adalah salah satu ayat paling destruktif dalam sejarah hukum agama. Ia menetapkan kepemimpinan laki-laki atas perempuan, kemudian memberi suami tiga instrumen kontrol atas istri yang "nusyuz": nasihat, pisah ranjang, dan — pemukulan. Tidak ada ambiguitas di sini. Ini bukan metafora, bukan tafsir yang diperdebatkan — ini izin legal untuk kekerasan fisik dalam rumah tangga. Alasan yang diberikan untuk kepemimpinan laki-laki pun bersifat melingkar: mereka "dipilih" karena Allah "melebihkan" mereka, tanpa kriteria "kelebihan" yang dapat diverifikasi. Ayat 15 menambahkan lapisan diskriminasi: perempuan yang terbukti "berbuat keji" harus dikurung sampai mati atau "sampai Allah memberi jalan lain." Sementara itu, ayat 16 memperlakukan "dua orang" yang melakukan perbuatan yang sama dengan hukuman yang dapat dihapus cukup dengan bertaubat. Perbedaan hukuman yang mencolok ini tidak dijelaskan — ia hanya ditetapkan. **III. Perbudakan Seksual sebagai Hukum Agama** Ayat 24 secara eksplisit mengecualikan perempuan budak dari perlindungan yang diberikan kepada perempuan merdeka: mereka boleh digunakan secara seksual oleh pemiliknya. Tidak ada kewajiban persetujuan, tidak ada mahar, tidak ada wali. Ini bukan penafsiran pinggiran — ini adalah teks yang jelas. Surat yang berjudul "Perempuan" melindungi perempuan merdeka dengan seperangkat hak, sementara menciptakan kelas perempuan yang tidak memiliki hak apapun atas tubuh mereka sendiri. Ayat 25 kemudian menambahkan bahwa budak yang berzina dihukum setengah dari perempuan merdeka — seolah jiwa manusia dapat dikuantifikasi berdasarkan status sosial. **IV. Doktrin Perang Agama dan Dehumanisasi** Separuh kedua surat ini beralih ke konteks militer Madinah, membangun doktrin jihad yang bermasalah. Ayat 89 memerintahkan: "tawan dan bunuhlah mereka di mana saja kamu menemuinya" — perintah eksplisit untuk kekerasan terhadap mereka yang "berpaling." Ayat 76 membangun dikotomi absolut: "orang beriman berperang di jalan Allah, orang kafir berperang di jalan tagut" — framing yang menghilangkan kemungkinan koeksistensi damai atau resolusi konflik non-kekerasan. Ayat 101 menyatakan "orang kafir adalah musuh yang nyata bagimu" — generalisasi yang tidak membedakan antara kelompok yang sedang berperang dan mereka yang hidup damai. Yang paling problematik secara teologis adalah ayat 88: Allah dinyatakan telah "membalikkan" orang munafik kepada kekafiran, namun mereka tetap dikecam dan diancam atas kekafiran yang ditentukan Allah sendiri. Paradoks ini — menghukum akibat dari tindakan Tuhan sendiri — merusak fondasi tanggung jawab moral seluruh sistem etika surat. **V. Antipati terhadap Yahudi sebagai Doktrin** Ayat 44-52, 155-162 membangun narasi kolektif negatif tentang Yahudi: mereka "membeli kesesatan," "mengubah perkataan dari tempatnya," "dikutuk Allah," dan "membunuh nabi-nabi." Stereotip ini tidak dibatasi pada individu atau kelompok tertentu dalam waktu tertentu — ia diterapkan secara kolektif kepada seluruh "orang Yahudi" (ayat 46, 160). Ini adalah teks yang secara historis menyumbang pada antisemitisme teologis. Ayat 157 secara khusus menyangkal penyaliban Yesus — klaim yang bertentangan dengan konsensus sejarah dari sumber Romawi (Tacitus) dan Yahudi (Josephus) abad pertama. Bukan sekadar perbedaan teologis, ini adalah klaim historis yang dapat diverifikasi dan salah. **VI. Sistem Kontrol Kosmik berbasis Ketakutan** Surat ini menggunakan surga dan neraka sebagai instrumen kontrol sosial secara berlebihan. Penolak hukum waris masuk neraka (ayat 14). Penolak Nabi sebagai hakim dinyatakan belum beriman (ayat 65). Orang yang beriman lalu kafir lalu beriman lagi tidak akan diampuni (ayat 137). Gambaran neraka yang paling mengerikan ada di ayat 56: kulit yang hangus terus diganti agar siksaan dapat dirasakan secara permanen. Ini bukan metafora — ini penggambaran sadisme yang diatribusikan kepada Allah "Yang Maha Bijaksana." Sistem ini menciptakan konformitas berbasis teror, bukan pemahaman etis yang otonom. Ketika seluruh sistem sosial, ekonomi, hukum, dan militer disandingkan dengan ancaman hukuman kosmik permanen, pertanyaan kritis menjadi tindakan pembangkangan teologis. **Kesimpulan** An-Nisa adalah surat hukum — bukan puisi spiritual atau refleksi teologis yang bisa ditafsirkan bebas. Ia menetapkan aturan konkret tentang warisan, pernikahan, perceraian, perang, dan hukuman. Aturan-aturan ini memiliki konsekuensi nyata bagi jutaan orang. Analisis kritis bukan serangan terhadap keyakinan individu, tetapi penilaian terhadap sistem hukum yang menetapkan dirinya sebagai final dan ilahi. Dari perspektif hak asasi manusia, surat ini melembagakan: kekerasan domestik (4:34), diskriminasi gender dalam warisan (4:11), perbudakan seksual (4:24), hukum ganda berbasis gender dan status sosial (4:15, 4:25), advokasi pembunuhan berbasis agama (4:89), dehumanisasi kelompok agama lain (4:46, 4:101), dan genosida teologis dalam bentuk hukuman kekal (4:56, 4:93). Bahwa semua ini diklaim sebagai perintah Tuhan yang tidak dapat diubah — itulah inti dari masalah yang dihadapi oleh setiap reformasi sosial di masyarakat yang menganut surat ini sebagai hukum. | H6: 92 | I6: Konteks Sejarah: Madinah - Pasca-Uhud, banyak janda/yatim piatu, dibutuhkan tatanan sosial baru Kondisi Psikologis: Membangun reformasi sosial yang komprehensif Motivasi Potensial: - Menggunakan perlindungan anak yatim untuk membangun otoritas moral - Membangun kerangka hak-hak perempuan yang terperinci - Menciptakan sistem warisan baru - Mengubah adat istiadat keluarga suku menjadi hukum Islam - Menetapkan peraturan perkawinan dan perceraian | J6: =COUNTIFS(bedah!$C:$C,Surat!$B6,bedah!I:I,"<>") -> 10 | K6: =J6/$E6 -> 0.056818182 | L6: =COUNTIFS(bedah!$C:$C,Surat!$B6,bedah!J:J,"<>") -> 176 | M6: =L6/$E6 -> 1 | N6: =COUNTIFS(bedah!$C:$C,Surat!$B6,bedah!K:K,"<>") -> 18 | O6: =N6/$E6 -> 0.10227273 | P6: =COUNTIFS(bedah!$C:$C,Surat!$B6,bedah!L:L,"<>") -> 27 | Q6: =P6/$E6 -> 0.15340909 | R6: =COUNTIFS(bedah!$C:$C,Surat!$B6,bedah!M:M,"<>") -> 5 | S6: =R6/$E6 -> 0.028409091 | T6: =COUNTIFS(bedah!$C:$C,Surat!$B6,bedah!N:N,"<>") -> 15 | U6: =T6/$E6 -> 0.085227273
A7: 5 | B7: الماۤئدة | C7: Al-Ma'idah | D7: Hidangan | E7: 120 | F7: Historical Context: Late Medina - Final major legislation, dealing with Jewish/Christian relations Psychological State: Completing religious law system Potential Motivations: - Using food laws to establish distinct identity - Building comprehensive contract fulfillment system - Creating clear interfaith interaction rules - Converting existing practices into final form - Establishing religious completion concept | G7: Al-Ma'idah: Hukuman Amputasi, Apartheid Agama, dan Kesalahan Teologis Surat Al-Ma'idah (Hidangan) adalah surat Madinah ke-112 dalam urutan turun wahyu, dengan 120 ayat yang mencakup hukum pidana, regulasi sosial lintas agama, narasi nabi-nabi Bani Israel, dan polemik teologis terhadap Kristen. Nama surat ini diambil dari episode "hidangan langit" (ayat 112-115) yang tidak memiliki padanan dalam tradisi Kristiani. Dari perspektif kritis, Al-Ma'idah adalah satu dokumen paling bermasalah dalam Al-Quran — menggabungkan hukuman fisik permanen, apartheid berbasis agama, stereotip kelompok, dan kesalahpahaman mendasar terhadap teologi Kristen. Hukuman Fisik Permanen: Penyaliban dan Amputasi (Ayat 33, 38) Ayat 33 menetapkan menu hukuman bagi yang "memerangi Allah dan Rasul": dibunuh, disalib, dipotong tangan dan kaki secara bersilangan, atau diasingkan. Ayat 38 memerintahkan potong tangan bagi pencuri. Keduanya bukan hukuman yang dapat dikoreksi jika kelak ditemukan kesalahan prosedural atau konteks yang meringankan. Penyaliban adalah bentuk eksekusi paling perlahan dan menyakitkan dalam sejarah — kematian bisa berlangsung berhari-hari. Bahwa sebuah teks yang mengklaim berasal dari Tuhan Yang Maha Pengasih memuatnya sebagai opsi legal adalah kontradiksi nilai yang fundamental. Lebih jauh, hukuman amputasi tangan pencuri menciptakan disabilitas permanen tanpa kemungkinan rehabilitasi, tidak membedakan konteks (mencuri karena kelaparan vs. kriminal profesional), dan tidak proporsional dengan beragam jenis pencurian. Standar hak asasi manusia internasional dengan eksplisit mengkategorikan amputasi judisial sebagai penyiksaan. Sistem Keadilan Primitif: Lex Talionis (Ayat 45) Ayat 45 menetapkan prinsip "jiwa dengan jiwa, mata dengan mata, hidung dengan hidung, telinga dengan telinga, gigi dengan gigi." Sistem ini — dikenal sebagai lex talionis — telah ada ribuan tahun sebelum Islam dalam Kode Hammurabi (sekitar 1750 SM). Bahwa ia diulang dalam teks yang diklaim wahyu Tuhan final mengindikasikan stagnasi moral, bukan kemajuan. Sistem balas dendam simetris ini tidak mempertimbangkan konteks, tidak mendorong rekonsiliasi, menutup rehabilitasi pelaku, dan mengabadikan siklus kekerasan. Hukum pidana modern telah bergerak jauh melampaui lex talionis justru karena kita memahami bahwa keadilan bukan tentang simetri balasan, melainkan tentang pencegahan, rehabilitasi, dan perlindungan masyarakat. Apartheid Berbasis Agama: Larangan Menjadikan Non-Muslim sebagai Pemimpin (Ayat 51) Ayat 51 secara eksplisit melarang orang beriman mengambil Yahudi dan Kristen sebagai "auliyā'" (pemimpin/pelindung/sekutu dekat). Mereka yang melanggar disebut "satu dari mereka" — efektif dianggap murtad atau pengkhianat. Ini bukan sekadar waspada terhadap musuh yang sedang berperang; ini adalah segregasi sistematis berdasarkan identitas agama. Larangan ini menciptakan hierarki kewargaan de facto: Muslim sebagai kelas pertama yang berhak memimpin; Yahudi dan Kristen sebagai kelas yang tidak berhak memimpin dan patut dicurigai. Dalam konteks masyarakat plural, doktrin ini — jika diterapkan secara literal — menjadi fondasi teologis diskriminasi struktural dan eksklusivisme politik. Kontradiksi Internal tentang Ahli Kitab (Ayat 51 vs. 82) Yang membuat ayat 51 semakin tidak koheren adalah kontradiksinya dengan ayat 82 dalam surat yang sama. Ayat 82 menyatakan bahwa "orang-orang yang mengatakan kami Nasrani" adalah "yang paling dekat cintanya kepada orang beriman." Ayat 51 menginstruksikan jangan menjadikan Nasrani sebagai pemimpin karena mereka bersekutu dengan Yahudi. Kedua pernyataan ini tidak bisa benar secara bersamaan: seseorang tidak mungkin sekaligus "paling dekat cintanya" dan layak dikucilkan dari kepemimpinan. Inkonsistensi ini mencerminkan teks yang berkembang dalam konteks politik berubah-ubah, bukan panduan yang koheren. Stereotip Kolektif dan Ujaran Kebencian terhadap Yahudi (Ayat 41, 64, 78, 82) Al-Ma'idah memuat narasi anti-Yahudi yang sistematik. Ayat 41 menyebut mereka "sangat suka mendengar berita bohong." Ayat 64 mengatakan mereka berkata "tangan Allah terbelenggu" lalu mengutuk "tangan mereka yang terkutuk" — penghukuman kolektif atas pernyataan yang paling tidak dilontarkan oleh segelintir orang. Ayat 78-79 menyebut mereka dilaknat oleh Daud dan Isa karena kemaksiatan. Ayat 82 menyatakan Yahudi adalah "paling keras permusuhannya" terhadap orang beriman. Penggeneralisasian ini bukan kritik atas tindakan spesifik individu atau kelompok tertentu dalam konteks historis tertentu — ini adalah atribusi sifat kolektif permanen kepada seluruh komunitas berdasarkan identitas agama mereka. Pola ini memenuhi definisi modern ujaran kebencian berbasis agama. Kesalahan Teologis: Salah Memahami Doktrin Trinitas (Ayat 72-75, 116) Ini adalah salah satu masalah paling terdokumentasi dalam Al-Quran. Ayat 72-75 mencoba membantah ketuhanan Isa dengan argumen bahwa "Al-Masih putra Maryam tidak lain adalah seorang rasul" dan bahwa ia serta ibunya "biasa memakan makanan" — namun representasi ini tidak menyentuh Trinitas Kristen yang sesungguhnya (Bapa, Anak, Roh Kudus). Lebih parah lagi, ayat 116 menggambarkan Allah bertanya kepada Isa: "Adakah kamu mengatakan kepada manusia: jadikanlah aku dan ibuku sebagai dua tuhan selain Allah?" Tidak ada sekte Kristen mainstream yang pernah memasukkan Maria sebagai anggota Trinitas. Trinitas Kristen adalah Bapa, Anak, dan Roh Kudus — bukan Bapa, Isa, dan Maria. Kesalahan ini berulang juga dalam surat lain (4:171) dan menunjukkan bahwa penyusun teks ini memiliki pemahaman yang keliru tentang doktrin Kristen yang menjadi sasaran polemiknya. Sebuah bantahan yang menggunakan straw man bukan hanya tidak efektif — ia juga membuktikan ketidaktahuan sang pembantah. Larangan Berpikir Kritis (Ayat 101) Ayat 101 berisi peringatan eksplisit: "Janganlah kamu menanyakan hal-hal yang jika diterangkan kepadamu akan menyusahkan kamu." Ini adalah instruksi untuk tidak mengajukan pertanyaan kritis tentang hukum agama — bukan karena pertanyaannya tidak valid, melainkan karena jawabannya akan "menyusahkan." Logika ini adalah argumentum ad consequentiam: menghindari pertanyaan berdasarkan akibat emosionalnya. Dalam konteks sistem nilai yang sehat, pertanyaan kritis yang menantang — bahkan yang jawabannya tidak nyaman — justru lebih berharga daripada kepatuhan buta yang tidak pernah bertanya. Inkonsistensi tentang Khamar (Ayat 90 vs. 2:219) Larangan khamar dalam surat ini juga menampilkan inkonsistensi dengan surat lain. Ayat 2:219 mengakui adanya "manfaat bagi manusia" dalam khamar meskipun dosanya besar. Ayat 5:90-91 mendefinisikan khamar murni sebagai "perbuatan setan" yang harus dihindari sepenuhnya, tanpa pengakuan manfaat apapun. Perubahan sikap ini — dari "ada manfaat tapi dosa besar" menjadi "perbuatan setan" — mencerminkan eskalasi bertahap yang wajar dalam proses legislasi manusiawi, bukan konsistensi wahyu ilahi yang tidak berubah. Kekerasan Seksual Berbasis Teks: Posisi Perempuan dalam Ritual Wudhu (Ayat 6) Ayat 6 menetapkan bahwa "menyentuh perempuan" (lāmastum al-nisā') membatalkan wudhu. Framing ini memposisikan tubuh perempuan sebagai agen pencemar ritual — sumber kenajisan yang perlu diwaspadai dalam konteks ibadah. Ini bukan sekadar aturan teknis; ini adalah ekspresi pandangan patriarkal yang meresap ke dalam regulasi keagamaan, di mana perempuan diposisikan sebagai objek yang berpotensi "mengotori" laki-laki secara ritual. Kisah Hidangan Langit: Narasi tanpa Akar Historis (Ayat 112-115) Surat ini — yang namanya diambil dari episode ini — menceritakan murid-murid Isa meminta "hidangan dari langit" sebagai tanda. Tidak ada catatan historis dalam tradisi Kristiani tentang episode semacam ini. Satu-satunya paralel yang mungkin adalah Perjamuan Malam Terakhir (Last Supper), namun narasi Quran menyimpang signifikan. Lebih bermasalah lagi: Allah mengabulkan permintaan hidangan tersebut lalu mengancam hukuman "yang tidak pernah ditimpakan kepada siapapun" bagi yang kafir sesudahnya — respons tidak proporsional yang menciptakan jebakan teologis. Kesimpulan Al-Ma'idah bukan dokumen keadilan atau kasih sayang. Ia adalah teks yang melembagakan amputasi judisial, penyaliban, apartheid agama, stereotip kolektif terhadap komunitas Yahudi dan Kristen, kesalahpahaman doktrin Trinitas, larangan berpikir kritis, dan inkonsistensi internal yang tidak dapat direkonsiliasi. Surat yang diturunkan "hampir terakhir" dan diklaim sebagai legislasi final Islam justru menampilkan beberapa masalah paling fundamental dalam keseluruhan Al-Quran. Tuhan yang memang Maha Adil dan Maha Bijaksana semestinya tidak membutuhkan penyaliban, amputasi, atau larangan bertanya untuk membangun sistem hukum yang baik. | H7: 112 | I7: Konteks Sejarah: Akhir Madinah - Legislasi utama terakhir, yang mengatur hubungan Yahudi/Kristen Kondisi Psikologis: Menyelesaikan sistem hukum keagamaan Motivasi Potensial: - Menggunakan hukum makanan untuk membangun identitas yang berbeda - Membangun sistem pemenuhan kontrak yang komprehensif - Menciptakan aturan interaksi antaragama yang jelas - Mengkonversi praktik yang ada ke bentuk akhir - Membangun konsep penyelesaian keagamaan | J7: =COUNTIFS(bedah!$C:$C,Surat!$B7,bedah!I:I,"<>") -> 4 | K7: =J7/$E7 -> 0.033333333 | L7: =COUNTIFS(bedah!$C:$C,Surat!$B7,bedah!J:J,"<>") -> 120 | M7: =L7/$E7 -> 1 | N7: =COUNTIFS(bedah!$C:$C,Surat!$B7,bedah!K:K,"<>") -> 10 | O7: =N7/$E7 -> 0.083333333 | P7: =COUNTIFS(bedah!$C:$C,Surat!$B7,bedah!L:L,"<>") -> 19 | Q7: =P7/$E7 -> 0.15833333 | R7: =COUNTIFS(bedah!$C:$C,Surat!$B7,bedah!M:M,"<>") -> 5 | S7: =R7/$E7 -> 0.041666667 | T7: =COUNTIFS(bedah!$C:$C,Surat!$B7,bedah!N:N,"<>") -> 7 | U7: =T7/$E7 -> 0.058333333
A8: 6 | B8: الأنعام | C8: Al-An'am | D8: Binatang Ternak | E8: 165 | F8: Historical Context: Intense polytheistic debate period Psychological State: Argumentative and establishing monotheistic logic Potential Motivations: - Using Abraham's story to dismantle idol worship logically - Building comprehensive argument against polytheism - Creating natural phenomena as signs framework - Converting Arabian customs into monotheistic framework - Establishing clear dietary/ritual laws against pagan practices | G8: Al-An'am adalah surat Makkiyah terpanjang, turun di tengah konfrontasi langsung antara Muhammad dan kaum musyrik Quraisy. Dengan 165 ayat, surat ini membangun argumen teologis yang sangat terstruktur — dan sekaligus memperlihatkan tumpukan persoalan logis, etis, dan ilmiah yang signifikan. PARADOKS DETERMINISME DAN HUKUMAN Persoalan paling mendasar dalam Al-An'am adalah kontradiksi teologis yang berulang: Allah diklaim secara aktif menyesatkan sebagian manusia — menutup hati mereka (6:25), mempalingkan hati dan penglihatan mereka (6:110), menjadikan dada mereka sempit sehingga tidak dapat menerima Islam (6:125) — kemudian menghukum mereka atas kesesatan yang Allah sendiri ciptakan. Ini bukan keadilan. Ini adalah sistem hukuman atas kondisi yang diciptakan oleh pihak yang menghukum. Hakim yang menciptakan kejahatan lalu mengadilinya bukan hakim — melainkan tirani yang menyelubungi diri dengan bahasa keadilan. Paradoks ini diperparah oleh ayat 35: "Jika Allah menghendaki, Dia bisa mengumpulkan mereka semua di atas petunjuk." Allah diklaim memiliki kemampuan untuk menjadikan semua orang beriman — namun memilih tidak melakukannya, lalu menghukum mereka yang tidak beriman. Ini bukan tes kebebasan berkehendak. Ini adalah permainan yang hasilnya sudah ditentukan, namun pesertanya tetap dihukum seolah-olah ada pilihan. SISTEM ANCAMAN SEBAGAI FONDASI TEOLOGIS Al-An'am menggunakan ancaman sebagai argumen utamanya. Hampir setiap segmen diisi dengan deskripsi siksa: azab dari atas dan bawah (6:65), pemusnahan sampai ke akar-akarnya (6:45), minuman dari air mendidih (6:70), gambaran penyesalan di hadapan neraka (6:27-31), dan kematian tiba-tiba (6:61). Ini bukan teologi — ini manajemen melalui teror psikologis. Keimanan yang lahir dari ancaman bukan keyakinan yang bebas. Ketika seseorang percaya karena takut siksaan bukan karena evaluasi kritis terhadap bukti, yang terbentuk adalah ketundukan paksa, bukan keyakinan yang genuine. Paradoksnya: surat yang mengklaim menawarkan petunjuk justru menutup setiap jalan menuju evaluasi bebas. PENOLAKAN BUKTI YANG TERSTRUKTUR Surat ini membangun mekanisme penolakan permintaan bukti yang elegan namun tidak jujur. Ketika orang meminta tulisan dari langit, dijawab bahwa mereka tetap akan menyebutnya sihir (6:7). Ketika orang meminta malaikat, dijawab bahwa kalau malaikat diturunkan semuanya akan dibinasakan (6:8-9). Ketika orang bersumpah bahwa dengan mukjizat mereka akan beriman, dijawab bahwa sekalipun ada mukjizat mereka tetap tidak akan beriman (6:109). Ini adalah strategi yang sistematis untuk menghindari kewajiban menghadirkan bukti yang dapat diverifikasi. Setiap permintaan bukti direspons dengan meramalkan bahwa pemohon pasti akan menolak — membuat klaim secara definitif tidak dapat difalsifikasi. Sistem kepercayaan yang tidak tahan terhadap pemeriksaan bukan sistem yang kuat; ia adalah sistem yang rapuh dan sadar akan kelemahannya. MASALAH SAINS Surat ini mengandung beberapa klaim yang bertentangan dengan pengetahuan ilmiah modern. Ayat 38 menyatakan bahwa semua hewan dan burung adalah "umat seperti kamu" — klaim yang mengabaikan fakta bahwa banyak spesies bersifat soliter dan tidak membentuk komunitas sosial. Ayat 96 mencerminkan pandangan kosmologis geosentris abad ke-7. Ayat 98 mengklaim seluruh umat manusia berasal dari "satu jiwa" — bertentangan dengan seluruh bangunan teori evolusi dan genetika populasi modern. Paling mencolok adalah ayat 125 yang mengklaim bahwa dada manusia "terasa sempit" di ketinggian tinggi karena Allah menyesatkan — sementara fisiologi modern menunjukkan sebaliknya: paru-paru mengembang dan bernapas lebih cepat untuk mengkompensasi kadar oksigen yang berkurang. KISAH IBRAHIM SEBAGAI RETROACTIVE ISLAMIZATION Narasi Ibrahim dalam surat ini (6:74-90) merupakan contoh konstruksi ulang figur historis untuk kepentingan narasi yang sedang dibangun. Ibrahim digambarkan melalui proses "mencari Tuhan" dengan menguji bintang, bulan, dan matahari — sebuah narasi yang tidak ditemukan dalam teks Ibrani yang lebih tua dan kemungkinan besar adalah penambahan dari penulis Al-Qur'an. Tujuannya jelas: membangun Ibrahim sebagai "Muslim pertama" sebelum Musa dan Yesus, sehingga Islam bukan agama baru tetapi agama yang paling tua dan otentik. Pola ini — mengklaim tokoh-tokoh tradisi lain sebagai bagian dari satu narasi tunggal — adalah strategi legitimasi, bukan pelaporan sejarah. Ketika seorang nabi kemudian mengklaim Nuh, Ibrahim, Musa, dan Isa semua sebenarnya adalah pendahulunya, ia tidak sedang merekam fakta; ia sedang mencaplok warisan. KONTRADIKSI INTERNAL Al-An'am memperlihatkan sejumlah kontradiksi yang tidak dapat diselesaikan secara internal. Tentang kesesatan: 6:12 menyatakan manusia "menzalimi diri sendiri" sementara 6:25 dan 6:39 menyatakan Allah yang menutup hati mereka. Tentang hari kiamat: 6:22-24 menyatakan orang kafir dapat melihat di akhirat, sementara 20:124-125 menyatakan mereka dibangkitkan buta. Tentang Muslim pertama: 6:14 dan 6:163 keduanya mengklaim Muhammad adalah yang pertama berserah diri, sementara narasi lain menunjukkan Nuh dan Lot sudah disebut Muslim jauh sebelumnya. Kontradiksi tentang beban dosa sangat mencolok: 6:164 dengan tegas menyatakan "setiap jiwa hanya menanggung dosanya sendiri, tidak ada jiwa yang menanggung dosa jiwa lain" — sementara 5:29 dan 16:25 menyatakan seseorang bisa menanggung dosa orang lain. Kontradiksi tentang keabadian neraka juga hadir: 6:128 memberi pengecualian "kecuali Allah menghendaki lain" — yang bertentangan dengan doktrin kekekalan neraka. ATURAN MAKANAN TANPA DASAR YANG BISA DIVERIFIKASI Bagian besar dari surat ini diisi dengan regulasi makanan halal-haram (6:118-145). Aturan-aturan ini tidak disertai penjelasan rasional yang dapat dievaluasi secara ilmiah — hanya otoritas. Yang lebih bermasalah: Allah diklaim memberikan pengharaman yang lebih ketat kepada orang Yahudi sebagai "hukuman atas kezaliman mereka" (6:146). Ini adalah diskriminasi hukum berdasarkan identitas kelompok — berbeda standar untuk kelompok berbeda bukan karena pertimbangan substantif, tetapi karena status teologis kelompok tersebut. KESIMPULAN Al-An'am adalah surat yang membangun fondasi teologis melalui intimidasi, menyumbat permintaan bukti melalui prediksi yang tidak dapat difalsifikasi, melegitimasi diskriminasi melalui otoritas ilahi, dan menciptakan paradoks etis fundamental antara kemahakuasaan Allah dan tanggung jawab manusia. Surat ini bukan wahyu tentang keadilan universal — ia adalah sistem kontrol yang canggih, yang secara sistematis menutup setiap pintu bagi evaluasi bebas sambil menuntut pertanggungjawaban penuh dari manusia atas kondisi yang sedari awal ditentukan bukan oleh mereka. | H8: 55 | I8: Konteks Sejarah: Periode perdebatan politeistik yang intens Kondisi Psikologis: Argumentatif dan membangun logika monoteistik Motivasi Potensial: - Menggunakan kisah Abraham untuk membongkar penyembahan berhala secara logis - Membangun argumen komprehensif melawan politeisme - Menciptakan fenomena alam sebagai kerangka tanda - Mengkonversi kebiasaan Arab ke dalam kerangka monoteistik - Menetapkan hukum diet/ritual yang jelas melawan praktik pagan | J8: =COUNTIFS(bedah!$C:$C,Surat!$B8,bedah!I:I,"<>") -> 9 | K8: =J8/$E8 -> 0.054545455 | L8: =COUNTIFS(bedah!$C:$C,Surat!$B8,bedah!J:J,"<>") -> 165 | M8: =L8/$E8 -> 1 | N8: =COUNTIFS(bedah!$C:$C,Surat!$B8,bedah!K:K,"<>") -> 151 | O8: =N8/$E8 -> 0.91515152 | P8: =COUNTIFS(bedah!$C:$C,Surat!$B8,bedah!L:L,"<>") -> 21 | Q8: =P8/$E8 -> 0.12727273 | R8: =COUNTIFS(bedah!$C:$C,Surat!$B8,bedah!M:M,"<>") -> 7 | S8: =R8/$E8 -> 0.042424242 | T8: =COUNTIFS(bedah!$C:$C,Surat!$B8,bedah!N:N,"<>") -> 13 | U8: =T8/$E8 -> 0.078787879
A9: 7 | B9: الأعراف | C9: Al-A'raf | D9: Tempat Tertinggi | E9: 206 | F9: Historical Context: Early detailed exposition of divine law and boundaries Psychological State: Comprehensive teaching and warning mode Potential Motivations: - Using extended Moses narrative to establish law-giving authority - Building detailed paradise/hell imagery from existing Arab concepts - Creating clear criterion between obedience and transgression - Converting existing moral concepts into structured framework - Addressing specific Jewish/Christian narratives present in Arabia | G9: Al-A'raf: Surat Panjang yang Mengekspos Fondasi Bermasalah Islam Surat Al-A'raf adalah satu dari surat terpanjang dalam Al-Quran (206 ayat) dan termasuk surat Makkiyah. Isinya mencakup kisah penciptaan Iblis, narasi Adam dan Hawa, serangkaian kisah penghukuman umat terdahulu (Nuh, 'Ad, Tsamud, Luth, Syu'aib, Musa), deskripsi hari kiamat dan sistem pakaian moral, hingga ajaran tentang tauhid. Membaca surat ini secara kritis mengungkap sejumlah persoalan serius yang tidak bisa diselesaikan dengan tafsir apologetis biasa. 1. TEODISI YANG GAGAL: ALLAH MENCIPTAKAN IBLIS UNTUK MENYESATKAN MANUSIA Salah satu isu paling fundamental dalam surat ini adalah paradoks penciptaan Iblis. Ayat 11–18 menggambarkan Allah memerintahkan malaikat sujud kepada Adam; Iblis menolak karena merasa lebih mulia (dari api, bukan tanah). Allah mengutuk Iblis — lalu secara eksplisit mengizinkan Iblis menggoda dan menyesatkan manusia sampai hari kiamat (ayat 14–18). Paradoks ini tidak bisa diselesaikan: kalau Allah mahakuasa dan mahamengetahui, Dia tahu sejak awal bahwa Iblis akan menolak dan bahwa kehadiran Iblis akan menyebabkan jutaan manusia sesat. Kalau Allah tetap menciptakan dan mengizinkan Iblis beroperasi, Allah adalah penyebab pertama (prima causa) dari kesesatan manusia. Menghukum manusia atas kesesatan yang infrastrukturnya dirancang sejak awal oleh penciptanya sendiri adalah kontradiksi moral yang mendasar. Lebih jauh, ayat 16 mencatat Iblis berkata: "Karena Engkau telah menyesatkan aku" — pernyataan yang tidak pernah dibantah Allah dalam teks. Ini mengimplikasikan bahwa bahkan Iblis mengakui dirinya adalah korban predestinasi, bukan pemberontak bebas. 2. NARASI ADAM DAN HAWA: KONTRADIKSI LINTAS SURAT DAN PEMBUKTIAN KASAR Ayat 22–25 menceritakan kisah Adam dan Hawa yang tergoda, meminta ampun, lalu diperintahkan turun ke bumi. Tapi dibandingkan dengan versi paralel dalam Surat 2:36–38 dan Surat 20:121–124, ada kontradiksi kronologis yang tidak bisa diabaikan. Dalam Surat 20, Adam diampuni sebelum diperintahkan turun. Dalam Surat 7, tidak ada pernyataan pengampunan — langsung ada perintah turun. Dalam Surat 2, perintah turun muncul dua kali (2:36 dan 2:38). Para sarjana akademis mencatat bahwa Surat 2 tampaknya menggabungkan versi Surat 7 dan Surat 20 secara tidak rapi, menciptakan narasi yang tumpang tindih. Ini bukan soal "tafsir berbeda." Ini soal apakah kronologi dalam kitab yang diklaim sempurna bisa saling bertentangan atau tidak. Jawabannya: ya, bisa — dan itu masalah. Selain itu, narasi ini mengandung persoalan moral: perempuan diposisikan sebagai yang lebih mudah tergoda (tradisi tafsir dominan). Konsep rasa malu atas tubuh (aurat) dipancarkan dari sini, dan menjadi fondasi sistem kontrol tubuh perempuan yang bertahan selama berabad-abad. 3. GENOSIDA TEOLOGIS: POLA PENGHANCURAN MASSAL SEBAGAI NARASI UTAMA Surat ini menghabiskan lebih dari separuh isinya untuk menceritakan penghancuran total umat-umat yang menolak nabinya: Kaum Nuh (ayat 59–64), Kaum 'Ad (65–72), Kaum Tsamud (73–79), Kaum Luth (80–84), Kaum Syu'aib (85–93), dan Kaum Firaun (103–136). Polanya identik dan berulang: nabi datang → umat menolak → Allah menghancurkan mereka semua. Yang perlu dikritisi adalah bukan saja kekerasan yang dinormalisasi, tapi logika di baliknya. Penghancuran bersifat kolektif — tidak ada mekanisme untuk melindungi individu yang mungkin tidak bersalah, anak-anak, atau mereka yang tidak pernah mendapat kesempatan mendengar dakwah dengan adil. Lebih jauh, dalam kasus Kaum Tsamud (ayat 78), mereka dinyatakan dibinasakan dengan gempa bumi — sementara Surat 54:31 menyebut "satu teriakan yang dahsyat" dan Surat 11:67 menyebut "suara keras yang menggelegar." Narasi yang sama dikisahkan dengan mekanisme kehancuran yang berbeda di tiga tempat berbeda — kontradiksi faktual yang mencederai klaim konsistensi teks. Post Hoc Ergo Propter Hoc adalah falasi logika yang mendominasi seluruh bagian ini: setiap bencana alam (gempa, angin topan, hujan batu, banjir) diklaim sebagai respons langsung atas penolakan agama. Tidak ada mekanisme kausalitas yang ditawarkan — hanya asersi yang diulang berkali-kali sampai terasa seperti hukum alam. 4. HOMOFOBIA YANG DIKLAIM SEBAGAI SEJARAH Ayat 80–81 menyatakan bahwa kaum Luth adalah "orang-orang yang pertama kali" melakukan hubungan sesama jenis. Klaim ini secara empiris keliru. Hubungan sesama jenis terdokumentasi dalam berbagai peradaban kuno — Mesir, Yunani, Roma, Mesopotamia — jauh sebelum kisah Luth berlangsung. Orientasi seksual juga terdokumentasi secara konsisten di ratusan spesies hewan. Namun persoalan yang lebih mendasar adalah framing moralnya: teks ini menggunakan kata "fahisyah" (perbuatan keji) dan "israf" (melampaui batas) untuk menggambarkan hubungan sesama jenis, tanpa memberikan penjelasan mengapa hubungan tersebut merusak atau merugikan pihak mana pun. Ini bukan argumen moral — ini labelisasi tanpa justifikasi, yang kemudian dijadikan dasar hukum pidana dan kekerasan sosial terhadap komunitas LGBTQ+ selama berabad-abad. 5. KOSMOLOGI YANG SALAH Ayat 54 menggambarkan "malam menutupi siang dengan cepat" — gambaran yang mencerminkan konsepsi kosmologis pra-ilmiah di mana malam dan siang adalah entitas yang saling mengejar. Ini bukan fenomena yang terjadi di seluruh alam semesta; ini adalah persepsi lokal dari permukaan bumi yang berotasi. Teks tidak pernah mengoreksi persepsi ini ke pemahaman heliosentris. Ayat 40 menyatakan tentang "gerbang-gerbang langit" — konsep kosmologi kuno yang menempatkan langit sebagai kubah berlapis dengan pintu-pintu. Ilmu astronomi modern tidak menemukan bukti keberadaan gerbang semacam itu. 6. PREDESTINASI VS. TANGGUNG JAWAB MORAL: KONTRADIKSI SISTEMIK Surat ini berulang kali menyatakan bahwa Allah menyesatkan siapa yang Dia kehendaki dan memberi petunjuk kepada siapa yang Dia kehendaki (ayat 155–156, 178, 186). Pernyataan ini tidak bisa diharmoniskan dengan konsep tanggung jawab moral yang menjadi dasar seluruh sistem hukum dan etika Islam. Kalau Allah yang menentukan siapa yang sesat dan siapa yang mendapat petunjuk, maka orang yang sesat tidak memilih kesesatannya. Menghukum mereka dengan siksa kekal di neraka atas pilihan yang bukan pilihan mereka sendiri adalah tirani, bukan keadilan. Teks tidak pernah menyelesaikan kontradiksi ini — ia hanya mengulanginya di berbagai tempat sambil mempertahankan keduanya secara bersamaan. 7. PERJANJIAN PRA-KELAHIRAN: PERSETUJUAN YANG TIDAK SAH Ayat 172 mengklaim bahwa Allah mengambil "kesaksian" dari seluruh keturunan Adam sebelum mereka lahir: "Bukankah Aku Tuhanmu?" dan mereka menjawab "Betul, kami bersaksi." Perjanjian ini kemudian dijadikan dasar mengapa manusia tidak bisa beralasan "kami tidak tahu" di hari kiamat. Ini adalah konstruksi persetujuan yang tidak bisa diterima: tidak seorang pun yang ada sekarang mengingat perjanjian tersebut, tidak ada yang bisa memverifikasinya, dan tidak ada yang bisa menolaknya. Dalam terminologi hukum modern, ini adalah kontrak yang dibuat tanpa kapasitas hukum yang memadai, tanpa informasi yang lengkap, dan tanpa kemungkinan penolakan — dengan kata lain, bukan kontrak yang sah. 8. FALASI LOGIKA YANG MENDOMINASI TEKS Surat ini adalah laboratorium falasi logika: Argumentum ad Baculum (ancaman) mendominasi: neraka digambarkan berkali-kali dengan detail yang semakin intens bukan untuk memberikan argumen, melainkan untuk menciptakan rasa takut sebagai motivator kepatuhan. Ad Hominem struktural: orang yang tidak percaya disamakan dengan "binatang ternak, bahkan lebih sesat" (ayat 179) dan anjing yang menjulurkan lidah (ayat 176) — bukan argumen yang membahas keberatan mereka, melainkan serangan terhadap martabat mereka. Post Hoc Ergo Propter Hoc: setiap bencana alam dikaitkan dengan penolakan agama tanpa mekanisme kausalitas. Petitio Principii: "terbuktilah kebenaran" setelah tongkat Musa menelan sihir penyihir (ayat 118) — mukjizat tidak bisa membuktikan klaim teologis karena standar pembuktian tidak pernah ditetapkan secara independen. 9. NARASI MUSA: KONTRADIKSI DENGAN SURAT PARALEL Kisah Musa dalam surat ini bertentangan dengan versi paralel di surat-surat lain dalam beberapa titik: Gelar yang diberikan kepada Firaun berbeda: Surat 7:104 mencatat Musa berkata "aku utusan Tuhan semesta alam," sementara Surat 20:47 mencatat instruksi yang berbeda. Reaksi para pembesar Firaun terhadap Musa berbeda antara Surat 7:109–112 dan Surat 26:34–35. Alasan Aaron saat dimarahi Musa tentang anak sapi emas berbeda antara 7:150 dan 20:90–95. Kalau ini wahyu dari sumber yang sama, narasi seharusnya konsisten. Inkonsistensi ini lebih mudah dijelaskan sebagai hasil komposisi manusia yang tidak sempurna daripada wahyu ilahi yang sempurna. 10. JANTUNG SEBAGAI PUSAT KOGNISI Ayat 179 menyatakan mereka yang tidak berpikir "memiliki hati tapi tidak digunakan untuk memahami." Ini mencerminkan pandangan pra-ilmiah yang menempatkan jantung (qalb) sebagai pusat kognisi dan inteligensi — sebuah kepercayaan umum di dunia kuno, yang telah dibantah oleh ilmu neurosains modern yang menetapkan otak sebagai pusat pemrosesan kognitif. KESIMPULAN Al-A'raf bukan sekadar surat panjang dengan kisah-kisah nabi. Ia adalah teks yang secara sistematis membangun fondasi bermasalah: teodisi yang mengizinkan kejahatan sekaligus menghukum pelakunya, narasi genosida yang disakralkan sebagai kehendak ilahi, homofobia yang diposisikan sebagai fakta sejarah, kosmologi yang salah, predestinasi yang menghancurkan tanggung jawab moral, dan perjanjian pra-kelahiran yang tidak bisa disetujui secara sadar. Surat ini didominasi oleh falasi logika (ancaman, serangan personal, generalisasi berlebihan, circular reasoning) bukan oleh argumen yang bisa diverifikasi. Kalau ini wahyu dari entitas Yang Maha Mengetahui dan Maha Adil, standar yang digunakan tidak konsisten dengan keadilan, empati, atau logika yang menjadi fondasi etika manusiawi. | H9: 39 | I9: Konteks Sejarah: Penjelasan rinci awal tentang hukum dan batasan ilahi Keadaan Psikologis: Mode pengajaran dan peringatan yang komprehensif Motivasi Potensial: - Menggunakan narasi Musa yang diperluas untuk menetapkan otoritas pemberi hukum - Membangun gambaran surga/neraka yang rinci dari konsep Arab yang ada - Menciptakan kriteria yang jelas antara ketaatan dan pelanggaran - Mengubah konsep moral yang ada menjadi kerangka kerja yang terstruktur - Menangani narasi Yahudi/Kristen spesifik yang ada di Arab | J9: =COUNTIFS(bedah!$C:$C,Surat!$B9,bedah!I:I,"<>") -> 5 | K9: =J9/$E9 -> 0.024271845 | L9: =COUNTIFS(bedah!$C:$C,Surat!$B9,bedah!J:J,"<>") -> 206 | M9: =L9/$E9 -> 1 | N9: =COUNTIFS(bedah!$C:$C,Surat!$B9,bedah!K:K,"<>") -> 45 | O9: =N9/$E9 -> 0.2184466 | P9: =COUNTIFS(bedah!$C:$C,Surat!$B9,bedah!L:L,"<>") -> 41 | Q9: =P9/$E9 -> 0.19902913 | R9: =COUNTIFS(bedah!$C:$C,Surat!$B9,bedah!M:M,"<>") -> 14 | S9: =R9/$E9 -> 0.067961165 | T9: =COUNTIFS(bedah!$C:$C,Surat!$B9,bedah!N:N,"<>") -> 10 | U9: =T9/$E9 -> 0.048543689
A10: 8 | B10: الأنفال | C10: Al-Anfal | D10: Rampasan Perang | E10: 75 | F10: Historical Context: Medina - After Badr battle, dealing with war spoils disputes Psychological State: Managing victory and internal disputes Potential Motivations: - Using battle events to establish authority - Building divine control over victory narrative - Creating clear spoils distribution system - Converting tribal customs into religious framework -Establishing obedience in conflict situations | G10: Al-Anfal: Surat ini berisi banyak aturan perang yang bermasalah kalau dilihat secara kritis. Ada beberapa masalah besar: Harta rampasan dijadikan rezeki halal: Surat ini menyatakan harta yang dirampas dari musuh dalam perang itu halal. Ini sama saja melegalkan perampokan asal atas nama agama. Ekonomi yang sehat tidak bisa dibangun dari merampok orang lain. Perintah sadis dalam perang: Ada ayat yang memerintahkan potong kepala dan pancung jari musuh. Sangat kejam — perang modern pun punya aturan untuk tidak menyiksa lawan. Menganggap non-Muslim seperti binatang: Ada ayat yang menyatakan orang kafir lebih rendah dari binatang. Ini merusak penghargaan terhadap sesama manusia dan membuka jalan bagi kekerasan terhadap yang berbeda agama. Klaim malaikat ikut berperang: Surat ini mengklaim malaikat turun membantu Muslim bertempur. Klaim seperti ini membuat perang terlihat sah secara kosmis — dan itu justru berbahaya. Melarang mundur dari perang: Ada larangan tegas untuk mundur dari pertempuran. Ini memaksa orang terus bertempur meski situasinya sudah berbahaya, dan bisa berujung pada kematian sia-sia. Membenarkan pengkhianatan perjanjian: Ada aturan yang membolehkan perjanjian damai diingkari kalau dianggap menguntungkan. Ini merusak kepercayaan dan membuat hubungan antar kelompok tidak pernah benar-benar stabil. Terorisme psikologis: Ada perintah untuk menakut-nakuti musuh sebesar mungkin. Ini bukan strategi militer biasa — ini terorisme yang disahkan teks. Template untuk kekerasan: Beberapa ayat dari surat ini sering dikutip kelompok radikal untuk membenarkan tindakan kekerasan mereka. Kesimpulan: Al-Anfal bukan wahyu tentang perdamaian — ini manual perang total yang mengajarkan perampokan, kekerasan, dan supremasi agama melalui kekuatan. Spiritualitas sejati seharusnya mengajarkan perdamaian dan menghargai sesama manusia, bukan potong kepala atau rampok harta musuh untuk "menyebarkan agama." | H10: 88 | I10: Konteks Sejarah: Madinah - Setelah Pertempuran Badr, menangani sengketa rampasan perang Kondisi Psikologis: Mengelola kemenangan dan perselisihan internal Motivasi Potensial: - Menggunakan peristiwa pertempuran untuk membangun otoritas - Membangun kendali ilahi atas narasi kemenangan - Menciptakan sistem distribusi rampasan perang yang jelas - Mengubah adat istiadat suku menjadi kerangka keagamaan - Membangun kepatuhan dalam situasi konflik | J10: =COUNTIFS(bedah!$C:$C,Surat!$B10,bedah!I:I,"<>") -> 2 | K10: =J10/$E10 -> 0.026666667 | L10: =COUNTIFS(bedah!$C:$C,Surat!$B10,bedah!J:J,"<>") -> 75 | M10: =L10/$E10 -> 1 | N10: =COUNTIFS(bedah!$C:$C,Surat!$B10,bedah!K:K,"<>") -> 61 | O10: =N10/$E10 -> 0.81333333 | P10: =COUNTIFS(bedah!$C:$C,Surat!$B10,bedah!L:L,"<>") -> 19 | Q10: =P10/$E10 -> 0.25333333 | R10: =COUNTIFS(bedah!$C:$C,Surat!$B10,bedah!M:M,"<>") -> 0 | S10: =R10/$E10 -> 0 | T10: =COUNTIFS(bedah!$C:$C,Surat!$B10,bedah!N:N,"<>") -> 3 | U10: =T10/$E10 -> 0.04
